from fastapi import FastAPI, HTTPException

from model import Todo

from database import (
    fetch_one_todo,
    fetch_all_todos,
    create_todo,
    update_todo,
    remove_todo,
)

app = FastAPI()


# an HTTP-specific exception class  to generate exception information

@app.get("/")
async def read_root():
    return {"Hello": "World"}

@app.get("/api/todo")
async def get_todo():
    response = await fetch_all_todos()
    return response

@app.get("/api/todo/{title}", response_model=Todo)
async def get_todo_by_title(title):
    response = await fetch_one_todo(title)
    if response:
        return response
    raise HTTPException(404, f"There is no todo with the title {title}")

@app.post("/api/todo/", response_model=Todo)
async def post_todo(todo: Todo):
    response = await create_todo(todo.dict())
    if response:
        return response
    raise HTTPException(400, "Something went wrong")

@app.put("/api/todo/{title}/", response_model=Todo)
async def put_todo(title: str, desc: str):
    response = await update_todo(title, desc)
    if response:
        return response
    raise HTTPException(404, f"There is no todo with the title {title}")

@app.delete("/api/todo/{title}")
async def delete_todo(title):
    response = await remove_todo(title)
    if response:
        return "Successfully deleted todo"
    raise HTTPException(404, f"There is no todo with the title {title}")

if __name__ == "__main__":
    uvicorn.run("main:app", host="0.0.0.0", port=8000)
